Workbook

Sheet Summary
H2: NGIDIH | I2: HARI H & RESEPSI
H3: 46822 | I3: 46909
B6: Wedding Planner | H6: COUNTDOWN
H7: =INT(H3-NOW()) -> 564 | I7: =INT(I3-NOW()) -> 651
B8: Rama & Sita
H9: Days Left 🔥 | I9: Days Left 🔥
B11: List | C11: Budget | F11: Checklist | H11: Total Budget Wedding | I11: =I22 -> 100400000000
C12: Alokasi | D12: Aktual | E12: Selisih | H12: Total Alokasi Budget | I12: =SUM($C$13:$C$29) -> 33000000
B13: Prewedding | C13: 0 | D13: =SUMIF(Pengeluaran!E:E, "Prewedding", Pengeluaran!G:G) -> 0 | E13: =C13-D13 -> 0 | F13: FALSE | H13: Total Pengeluaran | I13: =SUM($D$13:$D$29) -> 0
B14: MCU Pra Nikah | C14: 0 | D14: =SUMIF(Pengeluaran!E:E, "MCU Pra Nikah", Pengeluaran!G:G) -> 0 | E14: =C14-D14 -> 0 | F14: FALSE | H14: Selisih (Budget-Pengeluaran) | I14: =I11-I13 -> 100400000000
B15: Pre Marital Booster | C15: 0 | D15: =SUMIF(Pengeluaran!E:E, "Pre Marital Booster", Pengeluaran!G:G) -> 0 | E15: =C15-D15 -> 0 | F15: FALSE
B16: Cincin | C16: 20000000 | E16: =C16-D16 -> 20000000 | F16: TRUE | H16: Wedding Budget
B17: MUA Ngidih | C17: 3000000 | E17: =C17-D17 -> 3000000 | F17: FALSE | H17: Pria | I17: 100000000
B18: Acara Ngidih | C18: 0 | D18: =SUMIF(Pengeluaran!E:E, "Acara Ngidih", Pengeluaran!G:G) -> 0 | E18: =C18-D18 -> 0 | F18: FALSE | H18: Keluarga Pria | I18: 100000000
B19: Pakaian Ngidih | C19: 0 | D19: =SUMIF(Pengeluaran!E:E, "Pakaian Ngidih", Pengeluaran!G:G) -> 0 | E19: =C19-D19 -> 0 | F19: FALSE | H19: Wanita | I19: 100000000
B20: Banten | C20: 0 | D20: =SUMIF(Pengeluaran!E:E, "Banten", Pengeluaran!G:G) -> 0 | E20: =C20-D20 -> 0 | F20: FALSE | H20: Keluarga Wanita | I20: 100000000
B21: MUA Nganten&Resepsi | C21: 0 | D21: =SUMIF(Pengeluaran!E:E, "MUA Nganten&Resepsi", Pengeluaran!G:G) -> 0 | E21: =C21-D21 -> 0 | F21: FALSE | H21: Tetangga | I21: 100000000000
B22: Pakaian Nganten | C22: 0 | D22: =SUMIF(Pengeluaran!E:E, "Pakaian Nganten", Pengeluaran!G:G) -> 0 | E22: =C22-D22 -> 0 | F22: FALSE | H22: Total | I22: =SUM(I17:I21) -> 100400000000
B23: MUA Keluarga | C23: 0 | D23: =SUMIF(Pengeluaran!E:E, "Payas Resepsi", Pengeluaran!G:G) -> 0 | E23: =C23-D23 -> 0 | F23: FALSE
B24: Hari H&Resepsi | C24: 10000000 | E24: =C24-D24 -> 10000000 | F24: FALSE
B25: Dokumentasi | C25: 0 | D25: =SUMIF(Pengeluaran!E:E, "Dokumentasi", Pengeluaran!G:G) -> 0 | E25: =C25-D25 -> 0 | F25: FALSE
B26: Seserahan | C26: 0 | D26: =SUMIF(Pengeluaran!E:E, "Seserahan", Pengeluaran!G:G) -> 0 | E26: =C26-D26 -> 0 | F26: FALSE
B27: Wedding Essential | C27: 0 | D27: =SUMIF(Pengeluaran!E:E, "Wedding Essential", Pengeluaran!G:G) -> 0 | E27: =C27-D27 -> 0 | F27: FALSE
B28: Alat-alat Lainnya | C28: 0 | D28: =SUMIF(Pengeluaran!E:E, "Alat-alat Lainnya", Pengeluaran!G:G) -> 0 | E28: =C28-D28 -> 0 | F28: FALSE
B29: Transport | C29: 0 | D29: =SUMIF(Pengeluaran!E:E, "Transport", Pengeluaran!G:G) -> 0 | E29: =C29-D29 -> 0 | F29: FALSE
B30: Beauty Essential | C30: 0 | D30: =SUMIF(Pengeluaran!E:E, "Beauty Essential", Pengeluaran!G:G) -> 0 | E30: =C30-D30 -> 0 | F30: FALSE
B34: Note!
B35: TOLONG "MAKE A COPY" YA, DIAKUN KALIAN BIAR YANG LAIN BISA PAKAI JUGA
B36: Caranya, setelah kalian buka file ini, klik "file" dan klik "make a copy/buat salinan" :)
B37: Halo kakak2 seperjuangan, note ini nanti bisa kalian hapus ya
B38: Aku jelasin sedikit disini
B39: Budget alokasi silahkan kalian isi sendiri berapa kira2 budget kalian
B40: Budget aktual nanti ga perlu kalian otak atik, tinggal kalian isi aja di bagian pengeluaran, nanti otomatis akan masuk ke budget aktual ya
B41: TAPI, kalau kalian nambah list baru, kalian tinggal copy format budget aktual dikolom yg lain, kemudian ganti namanya sesuai dengan nama list
B42: contoh =SUMIF(Pengeluaran!E:E, "Pakaian Ngidih", Pengeluaran!G:G) nah tinggal ganti nama "pakaian ngidih"nya dengan nama list kalian
B43: Ketika kalian menambahkan item list baru, akan otomatis masuk ke bagian dropdown pengeluaran ya
B44: Dibagian Budget wedding juga tinggal kalian isi berapa, nanti akan otomatis masuk ke tabel diatasnya
B45: Biar cantik dan semangat buat plannernya, untuk gambar bunga, silahkan kalian pilih yg mana (ada dibagian belakang ya), nanti tinggal hapus yang tidak dipakai :D

Sheet Pengeluaran
B2: 💸Pengeluaran 💸
B4: No | C4: Tanggal | D4: Detail Pengeluaran | E4: Kategori | F4: Pembayaran | G4: Nominal | H4: Keterangan
B5: 1 | C5: 45751 | D5: DP Griya | E5: Hari H&Resepsi | F5: DP | G5: 20000000 | H5: Ini hanya contoh ya
B6: 2 | C6: 45752 | D6: DP cincin | E6: Cincin | F6: DP | G6: 10000000 | H6: Ini hanya contoh ya
B7: 3 | C7: 45753 | D7: Pelunasan MUA ngidih | E7: MUA Ngidih | F7: Pelunasan | G7: 2000000 | H7: Ini hanya contoh ya
B8: 4 | C8: 45754 | G8: 0
B9: 5 | C9: 45755 | G9: 0
B10: 6 | C10: 45756 | G10: 0
B11: 7 | C11: 45757 | G11: 0
B12: 8 | C12: 45758 | G12: 0
B13: 9 | C13: 45759 | G13: 0
B14: 10 | C14: 45760 | G14: 0
B15: 11 | C15: 45761 | G15: 0
B16: 12 | C16: 45762 | G16: 0
B17: 13 | C17: 45763 | G17: 0
B18: 14 | C18: 45764 | G18: 0
B19: 15 | C19: 45765 | G19: 0
... B23: 19 | C23: 45769 | G23: 0
B24: 20 | C24: 45770 | G24: 0 | J24: Note
B25: 21 | C25: 45771 | G25: 0 | J25: Kategori akan menyesuaikan "list" disheet sebelumnya
B26: 22 | C26: 45772 | G26: 0 | J26: Yang penting dibagian aktual budgetnya sudah sesuai namanya
B27: 23 | C27: 45773 | G27: 0
B28: 24 | C28: 45774 | G28: 0
B29: 25 | C29: 45775 | G29: 0
B30: 26 | C30: 45776 | G30: 0
B31: 27 | C31: 45777 | G31: 0
B32: 28 | C32: 45778 | G32: 0
B33: 29 | C33: 45818 | G33: 0
B34: 30 | C34: 45819 | G34: 0
B35: 31 | C35: 45820 | G35: 0
B36: 32 | C36: 45821 | G36: 0
B37: 33 | C37: 45822 | G37: 0
B38: 34 | C38: 45823 | G38: 0
... B76: 61 | C76: 45748 | G76: 0

Sheet Checklist
A2: TO DO | B2: STATUS | C2: DONE | D2: VENDOR | E2: DUE DATE | F2: SISA HARI | G2: CATATAN LAIN
A3: Mulai Pre Marital Booster H-6 | C3: FALSE | F3: =INT(E3-TODAY())& " Hari" -> -46257 Hari
A4: Mulai Pre Marital Booster H-3 | C4: FALSE | F4: =INT(E4-TODAY())& " Hari" -> -46257 Hari
A5: Pertemuan Keluarga | C5: FALSE | F5: =INT(E5-TODAY())& " Hari" -> -46257 Hari
A6: Nyari Duasa | C6: FALSE | F6: =INT(E6-TODAY())& " Hari" -> -46257 Hari
A7: MCU Pra Nikah | C7: FALSE | F7: =INT(E7-TODAY())& " Hari" -> -46257 Hari
A8: Cari Vendor Prewedding | C8: FALSE | F8: =INT(E8-TODAY())& " Hari" -> -46257 Hari
A9: Beli cincin nikah | C9: FALSE | F9: =INT(E9-TODAY())& " Hari" -> -46257 Hari
A10: Booking MUA Ngidih | C10: FALSE | F10: =INT(E10-TODAY())& " Hari" -> -46257 Hari
A11: Booking MUA pria | C11: FALSE | F11: =INT(E11-TODAY())& " Hari" -> -46257 Hari
A12: Cari Griya | C12: FALSE | F12: =INT(E12-TODAY())& " Hari" -> -46257 Hari
A13: Sewa Box seserahan | C13: FALSE | F13: =INT(E13-TODAY())& " Hari" -> -46257 Hari
A14: Booking MUA Resepsi | C14: FALSE | F14: =INT(E14-TODAY())& " Hari" -> -46257 Hari
... A40: Skin Prep | C40: FALSE | F40: =INT(E40-TODAY())& " Hari" -> -46257 Hari
C41: FALSE | F41: =INT(E41-TODAY())& " Hari" -> -46257 Hari
C42: FALSE | F42: =INT(E42-TODAY())& " Hari" -> -46257 Hari
C43: FALSE | F43: =INT(E43-TODAY())& " Hari" -> -46257 Hari
C44: FALSE | F44: =INT(E44-TODAY())& " Hari" -> -46257 Hari
C45: FALSE | F45: =INT(E45-TODAY())& " Hari" -> -46257 Hari
C46: FALSE | F46: =INT(E46-TODAY())& " Hari" -> -46257 Hari
C47: FALSE | F47: =INT(E47-TODAY())& " Hari" -> -46257 Hari
C48: FALSE | F48: =INT(E48-TODAY())& " Hari" -> -46257 Hari
C49: FALSE | F49: =INT(E49-TODAY())& " Hari" -> -46257 Hari

Sheet MUA
B1: Make Up Artist per 2025
B3: No | C3: Vendor | D3: Package | E3: Include | F3: Harga by Owner | G3: Harga by Team | H3: Sosial Media | I3: Kontak | J3: Available
B4: 1 | C4: Taksuning Bali | D4: Premium | E4: Payas Agung & Resepsi | F4: 7000000 | G4: - | I4: 0819-9917-1725 | J4: By Owner
E5: Kostum
E6: Make Up
E7: Hair Do
E8: Aksesoris
D9: Exclusive | E9: Payas Agung & Resepsi | F9: 9000000 | G9: -
E10: Kostum Mix baru&lama
E11: Make Up
E12: Hair Do
E13: Aksesoris
E14: Rias 1 Pendamping
D15: Platinum | E15: Payas Agung & Resepsi | F15: 12000000 | G15: -
E16: Kostum Mix baru&lama
E17: Make Up
E18: Hair Do
E19: Aksesoris
E20: Rias 2 Pendamping
D21: Lainnya | E21: Pendamping | F21: 200000
E22: Transport | F22: 500000
B23: 2 | C23: MoreMua | D23: Standart | E23: Payas Agung | F23: 7000000 | I23: 0821-4706-9180
E24: Resepsi | F24: 6000000
E25: Payas Agung & Resepsi | F25: 10000000
D26: Elegant | E26: Payas Agung | F26: 9000000
E27: Resepsi | F27: 7000000
E28: Payas Agung & Resepsi | F28: 14000000
D29: Lainnya | E29: Payas Ngidih | F29: 3200000
E30: Pendamping | F30: 400000
E31: Transport | F31: 200000
B32: 3 | C32: Gek Mas Natural Klasik | D32: Payas Only Make up and Haid Do | E32: Bunga Pendek | G32: 2500000 | I32: 0896-0583-2288 | J32: By Team
E33: Bunga Madya Tinggi | G33: 3000000
E34: Bunga Pendek Exclusive | G34: 3250000
E35: Bunga Madya Tinggi Exclusive | G35: 4250000
D36: Pawiwahan Payas Agung dan Madya | E36: Silver | G36: 5500000
E37: Gold | G37: 7500000
E38: Platinum | G38: 10000000
E39: Exclusive | G39: 12500000
D40: Lainnya | E40: Transport | F40: 750000
B41: 4 | C41: MakeUp by Utari Dharma | D41: Paket Custom | E41: Payas Ngidih (Wanita) | G41: 2000000 | I41: 0895-3690-36091 | J41: By Team
...

Sheet Prewedding
B1: PREWEDDING✨
B3: TEMPAT PREWEDDING | F3: Bli Dek Maharupa | J3: Praba Royal Wedding
B4: Tempat | C4: Harga /2025 | D4: Keterangan | F4: 0878-6047-5476 | J4: 0819-9957-7648
B5: Art Center | C5: 1000000
B6: Air Terjun Blangsinga | C6: 300000
B7: Bajrasandi/renon | C7: 1000000
B8: Big Garden Corner | C8: 300000
B9: Benoa (sea safari) | C9: 500000
B10: Bali Farm | C10: 2500000
B11: Brown cafe | C11: 150000 | D11: per person
B12: Bukit asah | C12: 500000 | D12: Diluar tiket perorang
B13: Cafe Cosmic Sanur | C13: 500000
B14: Cafe Neun | C14: 500000
B15: Cafe Elago | C15: 950000
B16: Cafe Mirror | C16: 3500000 | D16: 3 jam
B17: Cafe Sama sama | C17: 500000
B18: Desa Tenganan | C18: 250000
B19: Danau buyan/tamblingan | C19: 1000000
B20: Danau Ulundanu | C20: 1000000
B21: Este Leisure | C21: 1200000
B22: Galih Ukir | C22: 500000
B23: Hidden Garden Studio | C23: 150000 | D23: Perjam
B24: Komaneka | C24: 2500000
B25: Kuda/unta mertasari | C25: 700000
B26: Kuda pantai saba | C26: 700000
B27: Kuda Pantai Nyanyi | C27: 700000
B28: Kebun raya bedugul | C28: 500000
B29: Kertagosa | C29: 500000
B30: Museum Bali | C30: 1000000
B31: Mousca Studio | C31: 250000
B32: Museum Lukisan | C32: 1000000
B33: Museum Blanco Ubud | C33: 1500000
B34: Museum Pendet | C34: 850000
B35: Museum Njana Tilem | C35: 1500000
B36: Monkey Forest | C36: 500000
B37: Montana Cafe | C37: 800000 | F37: Dewa Snapshot | J37: Note!
B38: Omma Day Club | C38: 1500000 | F38: 0812-3963-0603 | J38: Maaf disini cuma dikit pilihannya ya, memang saya maunya cuma 3 photografer ini :)
B39: Pantai Balangan | C39: 750000 | J39: Kalau mau disini bisa diisi list dari photografer yang kalian mau bandingkan :)
B40: Pantai Saba | C40: 300000 | D40: lokasi rumput
B41: Pantai Geger | C41: 400000
...

Sheet Daftar Undangan
B2: Daftar Undangan
B4: Undangan Calon Pengantin Pria | F4: Undangan Orangtua Calon Pengantin Pria | N4: Undangan Calon Pengantin Wanita | R4: Undangan OrangtuaCalon Pengantin Wanita
B5: No | C5: Nama | D5: Prioritas | E5: Jumlah | F5: No | G5: Nama | H5: Prioritas | I5: Jumlah | N5: No | O5: Nama | P5: Prioritas | Q5: Jumlah | R5: No | S5: Nama | T5: Prioritas | U5: Jumlah
B6: 1 | F6: 1 | N6: 1 | R6: 1
B7: 2 | F7: 2 | K7: Jumlah Undangan Pengantin Pria | L7: Jumlah Undangan Pengantin Wanita | N7: 2 | R7: 2
B8: 3 | F8: 3 | N8: 3 | R8: 3
B9: 4 | F9: 4 | N9: 4 | R9: 4
B10: 5 | F10: 5 | K10: =SUM(E:E)+SUM(I:I) -> 0 | L10: =SUM(Q:Q)+SUM(U:U) -> 0 | N10: 5 | R10: 5
B11: 6 | F11: 6 | N11: 6 | R11: 6
B12: 7 | F12: 7 | N12: 7 | R12: 7
B13: 8 | F13: 8 | N13: 8 | R13: 8
B14: 9 | F14: 9 | K14: Total Undangan | N14: 9 | R14: 9
B15: 10 | F15: 10 | N15: 10 | R15: 10
B16: 11 | F16: 11 | K16: =K10+L10 -> 0 | N16: 11 | R16: 11
B17: 12 | F17: 12 | N17: 12 | R17: 12
B18: 13 | F18: 13 | N18: 13 | R18: 13
B19: 14 | F19: 14 | N19: 14 | R19: 14
B20: 15 | F20: 15 | K20: Total Undangan | N20: 15 | R20: 15
B21: 16 | F21: 16 | K21: (Menikah digriya dengan waktu siang-sore) | N21: 16 | R21: 16
B22: 17 | F22: 17 | K22: =(K16*2)-((K16*2)*(20/100)) -> 0 | N22: 17 | R22: 17
B23: 18 | F23: 18 | N23: 18 | R23: 18
B24: 19 | F24: 19 | N24: 19 | R24: 19
B25: 20 | F25: 20 | N25: 20 | R25: 20
B26: 21 | F26: 21 | K26: Total Undangan | N26: 21 | R26: 21
B27: 22 | F27: 22 | K27: (Menikah dirumah hingga malam) | N27: 22 | R27: 22
B28: 23 | F28: 23 | K28: =(K16*2)+((K16*2)*(20/100)) -> 0 | N28: 23 | R28: 23
B29: 24 | F29: 24 | N29: 24 | R29: 24
B30: 25 | F30: 25 | N30: 25 | R30: 25
B31: 26 | F31: 26 | N31: 26 | R31: 26
B32: 27 | F32: 27 | N32: 27 | R32: 27
B33: 28 | F33: 28 | N33: 28 | R33: 28
B34: 29 | F34: 29 | N34: 29 | R34: 29
B35: 30 | F35: 30 | N35: 30 | R35: 30
B36: 31 | F36: 31 | N36: 31 | R36: 31
B37: 32 | F37: 32 | N37: 32 | R37: 32
B38: 33 | F38: 33 | N38: 33 | R38: 33
B39: 34 | F39: 34 | N39: 34 | R39: 34
B40: 35 | F40: 35 | N40: 35 | R40: 35
... B55: 50 | F55: 50 | N55: 50 | R55: 50
I58: NOTE!
...

Sheet Souvenir dan Seserahan
B2: Souvenir
B4: VENDOR | C4: ITEM | D4: HARGA | E4: LINK
B5: Item
B6: Harga
B7: Link
B11: Seserahan
B13: BOX | C13: ISIAN | D13: VENDOR | E13: HARGA | F13: Check
B14: Box 1 | C14: Cincin | E14: 0 | F14: FALSE
B15: Box 2 | C15: Emas 1000 gr | E15: 0 | F15: FALSE
C16: Liontin | E16: 0 | F16: FALSE
B17: Box 3 | E17: 0 | F17: FALSE
E18: 0 | F18: FALSE
E19: 0 | F19: FALSE
E20: 0 | F20: FALSE
E21: 0 | F21: FALSE
E22: 0 | F22: FALSE
E23: 0 | F23: FALSE
E24: 0 | F24: FALSE
E25: 0 | F25: FALSE
E26: 0 | F26: FALSE
E27: 0 | F27: FALSE
E28: 0 | F28: FALSE
A70: W

Sheet Dokumen
B2: Administrasi | I2: https://simkah4.kemenag.go.id/#
B3: Foto copy KTP dilegalisasi lurah | I3: 2 lembar
B4: Foto copy KK dilegalisasi lurah | I4: 2 lembar
B5: akta kelahiran | I5: Asli dan fotokopi 2 lembar
B6: ijazah terakhir
B7: Formulir Surat Pengantar Nikah dari Kepala Desa/Lurah (Model N1) | I7: Model N1 ditandatangani lurah atau kepala desa
B8: Formulir Permohonan Kehendak Nikah (model N2) | I8: Model N2 ditandatangani lurah atau kepala desa
B9: Surat persetujuan mempelai (Model N4) | I9: Model N4 ditandatangani lurah atau kepala desa
B10: Surat izin orang tua (Model N5) | I10: Model N5
B11: Pas foto suami dan istri berdampingan ukuran 4 x 6 berwarna | I11: 6 lembar
B12: Fotokopi KTP dua orang saksi selain orangtua | I12: 2 lembar
B13: Fotokopi KTP orangtua kedua mempelai | I13: 2 lembar | J13: https://id.shp.ee/ZLuHTBs
B14: Surat pernyataan belum pernah menikah dengan materai Rp6.000 dan diketahui oleh 2 orang saksi + stempel RT/RW setempat
B15: Surat nikah perkawinan agama | I15: 2 lembar | J15: https://id.shp.ee/iDzsDUc
B16: Proses Registrasi Online/Offline
A122: Hari H
A123: 1
A125: 2
A127: 3

Sheet Mood Board
A1: MOOD BOARD
B5: COLOR PALETTE | G5: RINGS
E6: Dominant warna | K6: Main Ring | N6: Referensi Lain
K7: Tipe :
B28: PREWEDDING ADAT BALI
B29: Looks
M30: Descriptions
B53: Lokasi
B54: Puri Rangki | J54: Puri Ageng Blahbatuh
B70: Pose
R71: Pose Konsep :
B194: PREWEDDING CASUAL
B195: Looks
K196: Descriptions
B216: Properties
K217: Descriptions
B232: Lokasi :
B248: Pose
B380: NGIDIH
B381: Looks
B382: Make Up | J382: Hair Do | Q382: Descriptions
Q383: Make Up :
Q393: Hair Do :
Q400: Wardrobe :
B435: HARI H
B436: Looks
B437: Make Up | J437: Hair Do | Q437: Descriptions
Q438: Make Up :
Q448: Hair Do :
Q455: Wardrobe :
B478: RESEPSI
B479: Looks
B480: Make Up | J480: Hair Do | Q480: Descriptions
Q481: Make Up :
Q491: Hair Do :
Q498: Wardrobe :

Sheet Hiasan
